Workbook
Name Slicer_Category: #N/A
Name Slicer_Region: #N/A

Sheet Dashboard
B2: RetailPulse Inc. — Regional Profitability Dashboard
B3: ="Data as of: "&TEXT(TODAY(),"mmmm dd, yyyy")&" | 6,500 transactions, FY2024-2025" -> Data as of: September 30, 2026 | 6,500 transactions, FY2024-2025
B8: Total Revenue | E8: Net Margin% | H8: Loss-Making Transactions | K8: Avg Discount Rate
B9: =SUM('Cleaned Data'!M2:M6501) -> 1653907.6 | E9: =AVERAGE('Cleaned Data'!O2:O6501) -> 0.38775664 | H9: =COUNTIF('Cleaned Data'!O2:O6501,"<0")/COUNTA('Cleaned Data'!A2:A6501) -> 0.017692308 | K9: =AVERAGE('Cleaned Data'!J2:J6501) -> 0.112392

Sheet Read Me
A1: RetailPulse Inc. — Raw Sales Transactions
A3: Source: Simulated POS export, FY2024-FY2025
A4: Rows: 6,598
A6: Purpose:
A7: This is a raw, unprocessed export as it would arrive from a POS/transactions system.
A8: It intentionally contains realistic data quality issues you would encounter on the job:
A10: Known issues to expect (do not fix here — clean on a copy):
A11: - Inconsistent text casing/spacing in Region and Category (e.g. 'north', 'NORTH ', 'North')
A12: - Inconsistent Date formats (ISO, US, day-first, and long-form text dates)
A13: - Missing values scattered in Date, Store, CustomerSegment, UnitPrice, DiscountPct, UnitCost, Returned
A14: - Inconsistent values in Returned (Yes/No, Y/N, 1/0, blank)
A15: - Duplicate transaction rows
... A20: Column Dictionary:
A21: TransactionID | B21: Unique identifier for each sales transaction
A22: Date | B22: Date of transaction (formats are inconsistent — needs standardizing)
A23: Region | B23: Sales region: North / South / East / West (casing inconsistent)
A24: Store | B24: Store code within region, e.g. N-003
A25: Category | B25: Product category (casing inconsistent)
A26: Product | B26: Product name
A27: CustomerSegment | B27: Member vs Non-Member (loyalty program status)
A28: UnitsSold | B28: Number of units sold in the transaction
A29: UnitPrice | B29: Selling price per unit, USD
A30: DiscountPct | B30: Discount applied, as a decimal fraction (0.10 = 10%)
A31: UnitCost | B31: Cost per unit to the business, USD
A32: Returned | B32: Whether the transaction was later returned (format inconsistent)

Sheet Cleaned Data
A1: TransactionID | B1: Date | C1: Region | D1: Store | E1: Category | F1: Product | G1: CustomerSegment | H1: UnitSold | I1: UnitPrice | J1: DiscountPct | K1: UnitCost | L1: Returned | M1: Revenue | N1: GrossProfit | O1: NetMarginPct | P1: Month | Q1: Quarter
A2: TXN-100001 | B2: 45832 | C2: North | D2: N-001 | E2: Grocery | F2: Snack Box | G2: Non-Member | H2: 2 | I2: 7.91 | J2: 0.068 | K2: 5.22 | L2: No | M2: =ROUND(H2*I2*(1-J2),2) -> 14.74 | N2: =ROUND(M2-(H2*K2),2) -> 4.3 | O2: =IFERROR(N2/M2,0) -> 0.2917232 | P2: =IF(B2="","",TEXT(B2,"mmm-yyyy")) -> Jun-2025 | Q2: =IF(B2="","","Q"&ROUNDUP(MONTH(B2)/3,0)&"-"&YEAR(B2)) -> Q2-2025
A3: TXN-100002 | B3: 45807 | C3: North | D3: N-010 | E3: Apparel | F3: Men's T-Shirt | G3: Non-Member | H3: 2 | I3: 24.84 | J3: 0 | K3: 10.8 | L3: No | M3: =ROUND(H3*I3*(1-J3),2) -> 49.68 | N3: =ROUND(M3-(H3*K3),2) -> 28.08 | O3: =IFERROR(N3/M3,0) -> 0.56521739 | P3: =IF(B3="","",TEXT(B3,"mmm-yyyy")) -> May-2025 | Q3: =IF(B3="","","Q"&ROUNDUP(MONTH(B3)/3,0)&"-"&YEAR(B3)) -> Q2-2025
A4: TXN-100003 | B4: 46007 | C4: South | D4: S-012 | E4: Grocery | F4: Sparkling Water 12pk | G4: Non-Member | H4: 1 | I4: 12.88 | J4: 0.245 | K4: 7.62 | L4: No | M4: =ROUND(H4*I4*(1-J4),2) -> 9.72 | N4: =ROUND(M4-(H4*K4),2) -> 2.1 | O4: =IFERROR(N4/M4,0) -> 0.21604938 | P4: =IF(B4="","",TEXT(B4,"mmm-yyyy")) -> Dec-2025 | Q4: =IF(B4="","","Q"&ROUNDUP(MONTH(B4)/3,0)&"-"&YEAR(B4)) -> Q4-2025
A5: TXN-100004 | B5: 45913 | C5: South | D5: S-012 | E5: Apparel | F5: Winter Jacket | G5: Member | H5: 2 | I5: 31.33 | J5: 0.229 | K5: 17.03 | L5: No | M5: =ROUND(H5*I5*(1-J5),2) -> 48.31 | N5: =ROUND(M5-(H5*K5),2) -> 14.25 | O5: =IFERROR(N5/M5,0) -> 0.29496999 | P5: =IF(B5="","",TEXT(B5,"mmm-yyyy")) -> Sep-2025 | Q5: =IF(B5="","","Q"&ROUNDUP(MONTH(B5)/3,0)&"-"&YEAR(B5)) -> Q3-2025
A6: TXN-100005 | B6: 45720 | C6: North | D6: N-007 | E6: Electronics | F6: Smart Watch | G6: Unknown | H6: 3 | I6: 191.02 | J6: 0.027 | K6: 147.29 | L6: No | M6: =ROUND(H6*I6*(1-J6),2) -> 557.59 | N6: =ROUND(M6-(H6*K6),2) -> 115.72 | O6: =IFERROR(N6/M6,0) -> 0.207536 | P6: =IF(B6="","",TEXT(B6,"mmm-yyyy")) -> Mar-2025 | Q6: =IF(B6="","","Q"&ROUNDUP(MONTH(B6)/3,0)&"-"&YEAR(B6)) -> Q1-2025
A7: TXN-100006 | B7: 45977 | C7: North | D7: N-015 | E7: Apparel | F7: Casual Dress | G7: Member | H7: 1 | I7: 81.01 | J7: 0.09 | K7: 43.16 | L7: No | M7: =ROUND(H7*I7*(1-J7),2) -> 73.72 | N7: =ROUND(M7-(H7*K7),2) -> 30.56 | O7: =IFERROR(N7/M7,0) -> 0.41454151 | P7: =IF(B7="","",TEXT(B7,"mmm-yyyy")) -> Nov-2025 | Q7: =IF(B7="","","Q"&ROUNDUP(MONTH(B7)/3,0)&"-"&YEAR(B7)) -> Q4-2025
A8: TXN-100007 | B8: 45810 | C8: South | D8: S-012 | E8: Electronics | F8: Wireless Earbuds | G8: Non-Member | H8: 3 | I8: 237.59 | J8: 0 | K8: 189.55 | L8: No | M8: =ROUND(H8*I8*(1-J8),2) -> 712.77 | N8: =ROUND(M8-(H8*K8),2) -> 144.12 | O8: =IFERROR(N8/M8,0) -> 0.20219706 | P8: =IF(B8="","",TEXT(B8,"mmm-yyyy")) -> Jun-2025 | Q8: =IF(B8="","","Q"&ROUNDUP(MONTH(B8)/3,0)&"-"&YEAR(B8)) -> Q2-2025
A9: TXN-100008 | B9: 45525 | C9: North | D9: N-007 | E9: Apparel | F9: Winter Jacket | G9: Non-Member | H9: 4 | I9: 32.08 | J9: 0.061 | K9: 14.54 | L9: No | M9: =ROUND(H9*I9*(1-J9),2) -> 120.49 | N9: =ROUND(M9-(H9*K9),2) -> 62.33 | O9: =IFERROR(N9/M9,0) -> 0.51730434 | P9: =IF(B9="","",TEXT(B9,"mmm-yyyy")) -> Aug-2024 | Q9: =IF(B9="","","Q"&ROUNDUP(MONTH(B9)/3,0)&"-"&YEAR(B9)) -> Q3-2024
A10: TXN-100009 | B10: 45551 | C10: North | D10: N-010 | E10: Grocery | F10: Sparkling Water 12pk | G10: Member | H10: 6 | I10: 19.04 | J10: 0.127 | K10: 10.94 | L10: No | M10: =ROUND(H10*I10*(1-J10),2) -> 99.73 | N10: =ROUND(M10-(H10*K10),2) -> 34.09 | O10: =IFERROR(N10/M10,0) -> 0.34182292 | P10: =IF(B10="","",TEXT(B10,"mmm-yyyy")) -> Sep-2024 | Q10: =IF(B10="","","Q"&ROUNDUP(MONTH(B10)/3,0)&"-"&YEAR(B10)) -> Q3-2024
A11: TXN-100010 | B11: 45683 | C11: South | D11: S-011 | E11: Apparel | F11: Men's T-Shirt | G11: Member | H11: 2 | I11: 39.05 | J11: 0.205 | K11: 15.81 | L11: No | M11: =ROUND(H11*I11*(1-J11),2) -> 62.09 | N11: =ROUND(M11-(H11*K11),2) -> 30.47 | O11: =IFERROR(N11/M11,0) -> 0.49073925 | P11: =IF(B11="","",TEXT(B11,"mmm-yyyy")) -> Jan-2025 | Q11: =IF(B11="","","Q"&ROUNDUP(MONTH(B11)/3,0)&"-"&YEAR(B11)) -> Q1-2025
A12: TXN-100011 | B12: 45653 | C12: East | D12: E-002 | E12: Electronics | F12: Power Bank | G12: Member | H12: 6 | I12: 111.54 | J12: 0.048 | K12: 83.47 | L12: Unknown | M12: =ROUND(H12*I12*(1-J12),2) -> 637.12 | N12: =ROUND(M12-(H12*K12),2) -> 136.3 | O12: =IFERROR(N12/M12,0) -> 0.21393144 | P12: =IF(B12="","",TEXT(B12,"mmm-yyyy")) -> Dec-2024 | Q12: =IF(B12="","","Q"&ROUNDUP(MONTH(B12)/3,0)&"-"&YEAR(B12)) -> Q4-2024
A13: TXN-100012 | B13: 45524 | C13: West | D13: W-003 | E13: Apparel | F13: Women's Jeans | G13: Non-Member | H13: 3 | I13: 93.22 | J13: 0.065 | K13: 44.82 | L13: No | M13: =ROUND(H13*I13*(1-J13),2) -> 261.48 | N13: =ROUND(M13-(H13*K13),2) -> 127.02 | O13: =IFERROR(N13/M13,0) -> 0.48577329 | P13: =IF(B13="","",TEXT(B13,"mmm-yyyy")) -> Aug-2024 | Q13: =IF(B13="","","Q"&ROUNDUP(MONTH(B13)/3,0)&"-"&YEAR(B13)) -> Q3-2024
... A79: TXN-100078 | B79: 45646 | C79: East | D79: E-004 | E79: Home Goods | F79: LED Desk Lamp | G79: Non-Member | H79: 8 | I79: 40.33 | J79: 0.051 | K79: 18.66 | L79: No | M79: =ROUND(H79*I79*(1-J79),2) -> 306.19 | N79: =ROUND(M79-(H79*K79),2) -> 156.91 | O79: =IFERROR(N79/M79,0) -> 0.51245958 | P79: =IF(B79="","",TEXT(B79,"mmm-yyyy")) -> Dec-2024 | Q79: =IF(B79="","","Q"&ROUNDUP(MONTH(B79)/3,0)&"-"&YEAR(B79)) -> Q4-2024
A80: TXN-100079 | C80: East | D80: E-014 | E80: Electronics | F80: Bluetooth Speaker | G80: Member | H80: 7 | I80: 39.32 | J80: 0.07 | K80: 28.93 | L80: No | M80: =ROUND(H80*I80*(1-J80),2) -> 255.97 | N80: =ROUND(M80-(H80*K80),2) -> 53.46 | O80: =IFERROR(N80/M80,0) -> 0.2088526
A81: TXN-100080 | B81: 45889 | C81: North | D81: N-013 | E81: Beauty | F81: Face Moisturizer | G81: Member | H81: 3 | I81: 47.22 | J81: 0.072 | K81: 20.89 | L81: No | M81: =ROUND(H81*I81*(1-J81),2) -> 131.46 | N81: =ROUND(M81-(H81*K81),2) -> 68.79 | O81: =IFERROR(N81/M81,0) -> 0.52327704 | P81: =IF(B81="","",TEXT(B81,"mmm-yyyy")) -> Aug-2025 | Q81: =IF(B81="","","Q"&ROUNDUP(MONTH(B81)/3,0)&"-"&YEAR(B81)) -> Q3-2025
A82: TXN-100081 | B82: 45859 | C82: North | D82: N-010 | E82: Electronics | F82: Wireless Earbuds | G82: Non-Member | H82: 4 | I82: 155.23 | J82: 0.059 | K82: 103.56 | L82: No | M82: =ROUND(H82*I82*(1-J82),2) -> 584.29 | N82: =ROUND(M82-(H82*K82),2) -> 170.05 | O82: =IFERROR(N82/M82,0) -> 0.29103699 | P82: =IF(B82="","",TEXT(B82,"mmm-yyyy")) -> Jul-2025 | Q82: =IF(B82="","","Q"&ROUNDUP(MONTH(B82)/3,0)&"-"&YEAR(B82)) -> Q3-2025
A83: TXN-100082 | B83: 45889 | C83: West | D83: W-012 | E83: Electronics | F83: Smart Watch | G83: Non-Member | H83: 1 | I83: 71.14 | J83: 0.03 | K83: 52.72 | L83: No | M83: =ROUND(H83*I83*(1-J83),2) -> 69.01 | N83: =ROUND(M83-(H83*K83),2) -> 16.29 | O83: =IFERROR(N83/M83,0) -> 0.23605275 | P83: =IF(B83="","",TEXT(B83,"mmm-yyyy")) -> Aug-2025 | Q83: =IF(B83="","","Q"&ROUNDUP(MONTH(B83)/3,0)&"-"&YEAR(B83)) -> Q3-2025
A84: TXN-100083 | B84: 45519 | C84: North | D84: N-013 | E84: Beauty | F84: Lipstick | G84: Member | H84: 5 | I84: 13.62 | J84: 0 | K84: 4.14 | L84: No | M84: =ROUND(H84*I84*(1-J84),2) -> 68.1 | N84: =ROUND(M84-(H84*K84),2) -> 47.4 | O84: =IFERROR(N84/M84,0) -> 0.69603524 | P84: =IF(B84="","",TEXT(B84,"mmm-yyyy")) -> Aug-2024 | Q84: =IF(B84="","","Q"&ROUNDUP(MONTH(B84)/3,0)&"-"&YEAR(B84)) -> Q3-2024
A85: TXN-100084 | B85: 45388 | C85: West | D85: W-007 | E85: Beauty | F85: Shampoo 300ml | G85: Non-Member | H85: 5 | I85: 11.95 | J85: 0.194 | K85: 4.82 | L85: No | M85: =ROUND(H85*I85*(1-J85),2) -> 48.16 | N85: =ROUND(M85-(H85*K85),2) -> 24.06 | O85: =IFERROR(N85/M85,0) -> 0.49958472 | P85: =IF(B85="","",TEXT(B85,"mmm-yyyy")) -> Apr-2024 | Q85: =IF(B85="","","Q"&ROUNDUP(MONTH(B85)/3,0)&"-"&YEAR(B85)) -> Q2-2024
A86: TXN-100085 | B86: 45851 | C86: North | D86: N-012 | E86: Grocery | F86: Sparkling Water 12pk | G86: Non-Member | H86: 3 | I86: 20.72 | J86: 0.056 | K86: 13.87 | L86: No | M86: =ROUND(H86*I86*(1-J86),2) -> 58.68 | N86: =ROUND(M86-(H86*K86),2) -> 17.07 | O86: =IFERROR(N86/M86,0) -> 0.2908998 | P86: =IF(B86="","",TEXT(B86,"mmm-yyyy")) -> Jul-2025 | Q86: =IF(B86="","","Q"&ROUNDUP(MONTH(B86)/3,0)&"-"&YEAR(B86)) -> Q3-2025
A87: TXN-100086 | B87: 45920 | C87: North | D87: N-006 | E87: Home Goods | F87: LED Desk Lamp | G87: Member | H87: 2 | I87: 15.52 | J87: 0.031 | K87: 6.94 | L87: No | M87: =ROUND(H87*I87*(1-J87),2) -> 30.08 | N87: =ROUND(M87-(H87*K87),2) -> 16.2 | O87: =IFERROR(N87/M87,0) -> 0.53856383 | P87: =IF(B87="","",TEXT(B87,"mmm-yyyy")) -> Sep-2025 | Q87: =IF(B87="","","Q"&ROUNDUP(MONTH(B87)/3,0)&"-"&YEAR(B87)) -> Q3-2025
A88: TXN-100087 | B88: 45949 | C88: West | D88: W-014 | E88: Home Goods | F88: Bath Towel Set | G88: Non-Member | H88: 4 | I88: 86.86 | J88: 0.174 | K88: 38.68 | L88: No | M88: =ROUND(H88*I88*(1-J88),2) -> 286.99 | N88: =ROUND(M88-(H88*K88),2) -> 132.27 | O88: =IFERROR(N88/M88,0) -> 0.46088714 | P88: =IF(B88="","",TEXT(B88,"mmm-yyyy")) -> Oct-2025 | Q88: =IF(B88="","","Q"&ROUNDUP(MONTH(B88)/3,0)&"-"&YEAR(B88)) -> Q4-2025
A89: TXN-100088 | B89: 45345 | C89: South | D89: S-007 | E89: Apparel | F89: Casual Dress | G89: Non-Member | H89: 4 | I89: 116.37 | J89: 0.13 | K89: 51.26 | L89: No | M89: =ROUND(H89*I89*(1-J89),2) -> 404.97 | N89: =ROUND(M89-(H89*K89),2) -> 199.93 | O89: =IFERROR(N89/M89,0) -> 0.49369089 | P89: =IF(B89="","",TEXT(B89,"mmm-yyyy")) -> Feb-2024 | Q89: =IF(B89="","","Q"&ROUNDUP(MONTH(B89)/3,0)&"-"&YEAR(B89)) -> Q1-2024
A90: TXN-100089 | B90: 45651 | C90: West | D90: W-008 | E90: Home Goods | F90: Storage Bin | G90: Member | H90: 1 | I90: 78.14 | J90: 0.104 | K90: 37.09 | L90: No | M90: =ROUND(H90*I90*(1-J90),2) -> 70.01 | N90: =ROUND(M90-(H90*K90),2) -> 32.92 | O90: =IFERROR(N90/M90,0) -> 0.47021854 | P90: =IF(B90="","",TEXT(B90,"mmm-yyyy")) -> Dec-2024 | Q90: =IF(B90="","","Q"&ROUNDUP(MONTH(B90)/3,0)&"-"&YEAR(B90)) -> Q4-2024
A91: TXN-100090 | B91: 45945 | C91: West | D91: W-004 | E91: Grocery | F91: Sparkling Water 12pk | G91: Member | H91: 1 | I91: 14 | J91: 0.074 | K91: 9.97 | L91: No | M91: =ROUND(H91*I91*(1-J91),2) -> 12.96 | N91: =ROUND(M91-(H91*K91),2) -> 2.99 | O91: =IFERROR(N91/M91,0) -> 0.23070988 | P91: =IF(B91="","",TEXT(B91,"mmm-yyyy")) -> Oct-2025 | Q91: =IF(B91="","","Q"&ROUNDUP(MONTH(B91)/3,0)&"-"&YEAR(B91)) -> Q4-2025
A92: TXN-100091 | B92: 45592 | C92: East | D92: E-003 | E92: Home Goods | F92: LED Desk Lamp | G92: Non-Member | H92: 2 | I92: 73.83 | J92: 0.059 | K92: 29.61 | L92: Yes | M92: =ROUND(H92*I92*(1-J92),2) -> 138.95 | N92: =ROUND(M92-(H92*K92),2) -> 79.73 | O92: =IFERROR(N92/M92,0) -> 0.57380353 | P92: =IF(B92="","",TEXT(B92,"mmm-yyyy")) -> Oct-2024 | Q92: =IF(B92="","","Q"&ROUNDUP(MONTH(B92)/3,0)&"-"&YEAR(B92)) -> Q4-2024
... A136: TXN-100135 | B136: 45841 | C136: South | D136: S-002 | E136: Home Goods | F136: Bath Towel Set | G136: Non-Member | H136: 1 | I136: 59.58 | J136: 0.201 | K136: 23.01 | L136: No | M136: =ROUND(H136*I136*(1-J136),2) -> 47.6 | N136: =ROUND(M136-(H136*K136),2) -> 24.59 | O136: =IFERROR(N136/M136,0) -> 0.51659664 | P136: =IF(B136="","",TEXT(B136,"mmm-yyyy")) -> Jul-2025 | Q136: =IF(B136="","","Q"&ROUNDUP(MONTH(B136)/3,0)&"-"&YEAR(B136)) -> Q3-2025
A137: TXN-100136 | C137: South | D137: S-004 | E137: Apparel | F137: Winter Jacket | G137: Member | H137: 10 | I137: 85.02 | J137: 0.247 | K137: 45.47 | L137: No | M137: =ROUND(H137*I137*(1-J137),2) -> 640.2 | N137: =ROUND(M137-(H137*K137),2) -> 185.5 | O137: =IFERROR(N137/M137,0) -> 0.2897532
A138: TXN-100137 | B138: 45709 | C138: East | D138: E-011 | E138: Home Goods | F138: Throw Pillow | G138: Non-Member | H138: 8 | I138: 45.34 | J138: 0.09 | K138: 18.22 | L138: No | M138: =ROUND(H138*I138*(1-J138),2) -> 330.08 | N138: =ROUND(M138-(H138*K138),2) -> 184.32 | O138: =IFERROR(N138/M138,0) -> 0.55841008 | P138: =IF(B138="","",TEXT(B138,"mmm-yyyy")) -> Feb-2025 | Q138: =IF(B138="","","Q"&ROUNDUP(MONTH(B138)/3,0)&"-"&YEAR(B138)) -> Q1-2025
A139: TXN-100138 | B139: 45921 | C139: West | D139: W-012 | E139: Electronics | F139: Smart Watch | G139: Member | H139: 20 | I139: 79.78 | J139: 0.086 | K139: 56.46 | L139: No | M139: =ROUND(H139*I139*(1-J139),2) -> 1458.38 | N139: =ROUND(M139-(H139*K139),2) -> 329.18 | O139: =IFERROR(N139/M139,0) -> 0.22571621 | P139: =IF(B139="","",TEXT(B139,"mmm-yyyy")) -> Sep-2025 | Q139: =IF(B139="","","Q"&ROUNDUP(MONTH(B139)/3,0)&"-"&YEAR(B139)) -> Q3-2025
A140: TXN-100139 | B140: 45738 | C140: South | D140: S-007 | E140: Home Goods | F140: Storage Bin | G140: Member | H140: 1 | I140: 33.67 | J140: 0.184 | K140: 15.32 | L140: No | M140: =ROUND(H140*I140*(1-J140),2) -> 27.47 | N140: =ROUND(M140-(H140*K140),2) -> 12.15 | O140: =IFERROR(N140/M140,0) -> 0.44230069 | P140: =IF(B140="","",TEXT(B140,"mmm-yyyy")) -> Mar-2025 | Q140: =IF(B140="","","Q"&ROUNDUP(MONTH(B140)/3,0)&"-"&YEAR(B140)) -> Q1-2025
A141: TXN-100140 | B141: 45323 | C141: West | D141: W-005 | E141: Electronics | F141: Bluetooth Speaker | G141: Non-Member | H141: 4 | I141: 275.42 | J141: 0.032 | K141: 209.81 | L141: No | M141: =ROUND(H141*I141*(1-J141),2) -> 1066.43 | N141: =ROUND(M141-(H141*K141),2) -> 227.19 | O141: =IFERROR(N141/M141,0) -> 0.21303789 | P141: =IF(B141="","",TEXT(B141,"mmm-yyyy")) -> Feb-2024 | Q141: =IF(B141="","","Q"&ROUNDUP(MONTH(B141)/3,0)&"-"&YEAR(B141)) -> Q1-2024
A142: TXN-100141 | B142: 45748 | C142: East | D142: E-013 | E142: Grocery | F142: Sparkling Water 12pk | G142: Member | H142: 1 | I142: 20.64 | J142: 0.069 | K142: 12.03 | L142: No | M142: =ROUND(H142*I142*(1-J142),2) -> 19.22 | N142: =ROUND(M142-(H142*K142),2) -> 7.19 | O142: =IFERROR(N142/M142,0) -> 0.37408949 | P142: =IF(B142="","",TEXT(B142,"mmm-yyyy")) -> Apr-2025 | Q142: =IF(B142="","","Q"&ROUNDUP(MONTH(B142)/3,0)&"-"&YEAR(B142)) -> Q2-2025
A143: TXN-100142 | B143: 45800 | C143: East | D143: E-011 | E143: Grocery | F143: Snack Box | G143: Non-Member | H143: 1 | I143: 16.82 | J143: 0.03 | K143: 11.53 | L143: No | M143: =ROUND(H143*I143*(1-J143),2) -> 16.32 | N143: =ROUND(M143-(H143*K143),2) -> 4.79 | O143: =IFERROR(N143/M143,0) -> 0.2935049 | P143: =IF(B143="","",TEXT(B143,"mmm-yyyy")) -> May-2025 | Q143: =IF(B143="","","Q"&ROUNDUP(MONTH(B143)/3,0)&"-"&YEAR(B143)) -> Q2-2025
A144: TXN-100143 | B144: 45820 | C144: East | D144: E-013 | E144: Apparel | F144: Casual Dress | G144: Non-Member | H144: 5 | I144: 53.31 | J144: 0.15 | K144: 22.37 | L144: No | M144: =ROUND(H144*I144*(1-J144),2) -> 226.57 | N144: =ROUND(M144-(H144*K144),2) -> 114.72 | O144: =IFERROR(N144/M144,0) -> 0.50633358 | P144: =IF(B144="","",TEXT(B144,"mmm-yyyy")) -> Jun-2025 | Q144: =IF(B144="","","Q"&ROUNDUP(MONTH(B144)/3,0)&"-"&YEAR(B144)) -> Q2-2025
A145: TXN-100144 | B145: 45843 | C145: East | D145: E-012 | E145: Apparel | F145: Women's Jeans | G145: Non-Member | H145: 1 | I145: 28.88 | J145: 0.125 | K145: 13.89 | L145: No | M145: =ROUND(H145*I145*(1-J145),2) -> 25.27 | N145: =ROUND(M145-(H145*K145),2) -> 11.38 | O145: =IFERROR(N145/M145,0) -> 0.45033637 | P145: =IF(B145="","",TEXT(B145,"mmm-yyyy")) -> Jul-2025 | Q145: =IF(B145="","","Q"&ROUNDUP(MONTH(B145)/3,0)&"-"&YEAR(B145)) -> Q3-2025
A146: TXN-100145 | B146: 45637 | C146: East | D146: E-014 | E146: Electronics | F146: Laptop Stand | G146: Non-Member | H146: 4 | I146: 106.16 | J146: 0 | K146: 82.86 | L146: No | M146: =ROUND(H146*I146*(1-J146),2) -> 424.64 | N146: =ROUND(M146-(H146*K146),2) -> 93.2 | O146: =IFERROR(N146/M146,0) -> 0.21948003 | P146: =IF(B146="","",TEXT(B146,"mmm-yyyy")) -> Dec-2024 | Q146: =IF(B146="","","Q"&ROUNDUP(MONTH(B146)/3,0)&"-"&YEAR(B146)) -> Q4-2024
A147: TXN-100146 | B147: 45882 | C147: West | D147: W-002 | E147: Electronics | F147: Wireless Earbuds | G147: Non-Member | H147: 2 | I147: 261.54 | J147: 0.106 | K147: 198.41 | L147: Unknown | M147: =ROUND(H147*I147*(1-J147),2) -> 467.63 | N147: =ROUND(M147-(H147*K147),2) -> 70.81 | O147: =IFERROR(N147/M147,0) -> 0.15142313 | P147: =IF(B147="","",TEXT(B147,"mmm-yyyy")) -> Aug-2025 | Q147: =IF(B147="","","Q"&ROUNDUP(MONTH(B147)/3,0)&"-"&YEAR(B147)) -> Q3-2025
A148: TXN-100147 | B148: 45445 | C148: East | D148: E-002 | E148: Grocery | F148: Organic Coffee 12oz | G148: Member | H148: 4 | I148: 8.82 | J148: 0.082 | K148: 5.01 | L148: No | M148: =ROUND(H148*I148*(1-J148),2) -> 32.39 | N148: =ROUND(M148-(H148*K148),2) -> 12.35 | O148: =IFERROR(N148/M148,0) -> 0.38129052 | P148: =IF(B148="","",TEXT(B148,"mmm-yyyy")) -> Jun-2024 | Q148: =IF(B148="","","Q"&ROUNDUP(MONTH(B148)/3,0)&"-"&YEAR(B148)) -> Q2-2024
...

Sheet KPI_Definitions
A1: KPI Name | B1: Formula/Logic | C1: Business Reason | D1: Target/Benchmark
A2: Total Revenue | B2: SUM of Revenue column | C2: Top-line performance | D2: Track growth vs prior period
A3: Net Margin % | B3: GrossProfit ÷ Revenue | C3: Core profitability health — your main business question | D3: Company target: 8%+ (currently ~6.5%, per Phase 1 brief)
A4: Discount Rate | B4: AVERAGE of DiscountPct | C4: Detects over-discounting, root cause candidate | D4: Flag if >15% average
A5: Return Rate | B5: Returned="Yes" ÷ Total transactions | C5: Detects hidden cost center | D5: Flag if >10%
A6: Loss-Making Transaction % | B6: COUNTIF NetMarginPct<0 ÷ Total | C6: Direct measure of your Key Finding #1 | D6: Target: <1%
A7: Revenue by Region | B7: SUMIFS by Region | C7: Identifies regional performance gaps | D7: Compare South vs other regions
A8: Revenue by Category | B8: SUMIFS by Category | C8: Identifies category performance gaps | D8: Compare Electronics vs other categories

Sheet Insight_Workings
A1: Region | B1: Loss-Making Transactions
A2: North | B2: =COUNTIFS('Cleaned Data'!C2:C6501,"North",'Cleaned Data'!O2:O6501,"<0") -> 3
A3: South | B3: =COUNTIFS('Cleaned Data'!C2:C6501,"South",'Cleaned Data'!O2:O6501,"<0") -> 111
A4: East | B4: =COUNTIFS('Cleaned Data'!C2:C6501,"East",'Cleaned Data'!O2:O6501,"<0") -> 1
A5: West | B5: =COUNTIFS('Cleaned Data'!C2:C6501,"West",'Cleaned Data'!O2:O6501,"<0") -> 0
A7: Electronics | B7: =COUNTIFS('Cleaned Data'!E2:E6501,"Electronics",'Cleaned Data'!O2:O6501,"<0") -> 101
A8: Apparel | B8: =COUNTIFS('Cleaned Data'!E2:E6501,"Apparel",'Cleaned Data'!O2:O6501,"<0") -> 0
A9: Home Goods | B9: =COUNTIFS('Cleaned Data'!E2:E6501,"Home Goods",'Cleaned Data'!O2:O6501,"<0") -> 3
A10: Grocery | B10: =COUNTIFS('Cleaned Data'!E2:E6501,"Grocery",'Cleaned Data'!O2:O6501,"<0") -> 11
A11: Beauty | B11: =COUNTIFS('Cleaned Data'!E2:E6501,"Beauty",'Cleaned Data'!O2:O6501,"<0") -> 0
A12: Total loss count | B12: =COUNTIF('Cleaned Data'!O2:O6501,"<0") -> 115
A13: Overall loss transaction pct | B13: =COUNTIF('Cleaned Data'!O2:O6501,"<0")/COUNTA('Cleaned Data'!A2:A6501) -> 0.017692308
A14: Electronics and south | B14: =COUNTIFS('Cleaned Data'!C2:C6501,"South",'Cleaned Data'!E2:E6501,"Electronics",'Cleaned Data'!O2:O6501,"<0") -> 99
A15: Discount given for Electronics x South | B15: =AVERAGEIFS('Cleaned Data'!J2:J6501,'Cleaned Data'!C2:C6501,"South",'Cleaned Data'!E2:E6501,"Electronics") -> 0.21717287
A16: Average discount of all transaction | B16: =AVERAGE('Cleaned Data'!J2:J6501) -> 0.112392

Sheet Pivot_MarginByRegionCat
A1: Row Labels | B1: Avg Net Margin%
A2: East | B2: 0.41371915
A3: Apparel | B3: 0.4766975
A4: Beauty | B4: 0.58183896
A5: Electronics | B5: 0.21761215
A6: Grocery | B6: 0.31914878
A7: Home Goods | B7: 0.54501664
A8: North | B8: 0.40638773
A9: Apparel | B9: 0.48275767
A10: Beauty | B10: 0.59006615
A11: Electronics | B11: 0.21299228
A12: Grocery | B12: 0.3065816
A13: Home Goods | B13: 0.53521511
... A26: Grand Total | B26: 0.38775664

Sheet Pivot_DiscountByRegionCat
A1: Row Labels | B1: Average of DiscountPct
A2: East | B2: 0.079939729
A3: Apparel | B3: 0.08104918
A4: Beauty | B4: 0.088024476
A5: Electronics | B5: 0.078146835
A6: Grocery | B6: 0.076678899
A7: Home Goods | B7: 0.077140575
A8: North | B8: 0.079251852
A9: Apparel | B9: 0.076066667
A10: Beauty | B10: 0.078349359
A11: Electronics | B11: 0.080430556
A12: Grocery | B12: 0.080648387
A13: Home Goods | B13: 0.080360902
... A26: Grand Total | B26: 0.112392

Sheet _x0009_Pivot_MonthlyTrend
A1: Row Labels | B1: Sum of Revenue | C1: Average of NetMarginPct
A2: 2024 | B2: 515335.49 | C2: 0.40554731
A3: Jan | B3: 2486.58 | C3: 0.40590291
A4: Feb | B4: 7656.62 | C4: 0.38445538
A5: Mar | B5: 12624.82 | C5: 0.4232517
A6: Apr | B6: 21876.66 | C6: 0.40881433
A7: May | B7: 28051.92 | C7: 0.40368985
A8: Jun | B8: 39961.96 | C8: 0.41768678
A9: Jul | B9: 43670.51 | C9: 0.42705217
A10: Aug | B10: 65148.8 | C10: 0.39841808
A11: Sep | B11: 71688.68 | C11: 0.39398458
A12: Oct | B12: 64763.79 | C12: 0.39137485
A13: Nov | B13: 72816.87 | C13: 0.40314654
... A28: Grand Total | B28: 1639357.5 | C28: 0.38780221

Sheet Forecast_Data
A1: Date | B1: Revenue_Actual | C1: Month_Index | D1: Linear_Forecast | E1: Seasonally-Adjusted Forecast
A2: 45292 | B2: 2486.58 | C2: 1
A3: 45323 | B3: 7656.62 | C3: 2
A4: 45352 | B4: 12624.82 | C4: 3 | G4: =B14/B13 -> 1.0623974
A5: 45383 | B5: 21876.66 | C5: 4 | G5: =B15/B14 -> 0.9225243
A6: 45413 | B6: 28051.92 | C6: 5 | G6: =B16/B15 -> 1.0608381
A7: 45444 | B7: 39961.96 | C7: 6
A8: 45474 | B8: 43670.51 | C8: 7
A9: 45505 | B9: 65148.8 | C9: 8
A10: 45536 | B10: 71688.68 | C10: 9
A11: 45566 | B11: 64763.79 | C11: 10
A12: 45597 | B12: 72816.87 | C12: 11
A13: 45627 | B13: 84588.28 | C13: 12
A14: 45658 | B14: 89866.37 | C14: 13
A15: 45689 | B15: 82903.91 | C15: 14
A16: 45717 | B16: 87947.63 | C16: 15
A17: 45748 | B17: 101029.5 | C17: 16
A18: 45778 | B18: 87117.84 | C18: 17
... A25: 45992 | B25: 72221.33 | C25: 24
A26: 46023 | C26: 25 | D26: =_xlfn.FORECAST.LINEAR(C26,$B$2:$B$25,$C$2:$C$25) -> 120983.3 | E26: =B25*(B14/B13) -> 76727.754
A27: 46054 | C27: 26 | D27: =_xlfn.FORECAST.LINEAR(C27,$B$2:$B$25,$C$2:$C$25) -> 125197.44 | E27: =E26*(B15/B14) -> 70783.218
A28: 46082 | C28: 27 | D28: =_xlfn.FORECAST.LINEAR(C28,$B$2:$B$25,$C$2:$C$25) -> 129411.58 | E28: =E27*(B16/B15) -> 75089.537

Sheet Raw Data
A1: TransactionID | B1: Date | C1: Region | D1: Store | E1: Category | F1: Product | G1: CustomerSegment | H1: UnitsSold | I1: UnitPrice | J1: DiscountPct | K1: UnitCost | L1: Returned
A2: TXN-105042 | B2: 04/03/2025 | C2: South | D2: S-001 | E2: Beauty | F2: Perfume 50ml | G2: Member | H2: 4 | I2: 35.34 | J2: 0.218 | K2: 10.9 | L2: No
A3: TXN-100765 | B3: 2025-04-27 | C3: South | D3: S-015 | E3: Home Goods | F3: LED Desk Lamp | G3: Member | H3: 1 | I3: 88.34 | J3: 0.171 | K3: 30.94 | L3: No
A4: TXN-103948 | B4: 03-07-2025 | C4: East | D4: E-004 | E4: Beauty | F4: Sunscreen SPF50 | G4: Member | H4: 5 | I4: 35.93 | J4: 0.1 | K4: 14.32 | L4: No
A5: TXN-100293 | B5: 04/06/2024 | C5: South | D5: S-003 | E5: Apparel | F5: Casual Dress | G5: Non-Member | H5: 2 | I5: 61.39 | J5: 0.268 | K5: 30.82 | L5: Y
A6: TXN-102532 | B6: 2025-08-31 | C6: East | D6: E-005 | E6: Electronics | F6: Bluetooth Speaker | G6: Member | H6: 1 | I6: 252.11 | J6: 0.1 | K6: 171.82 | L6: No
A7: TXN-101861 | B7: 2024-12-16 | C7: South | D7: S-008 | E7: Apparel | F7: Men's T-Shirt | G7: Member | H7: 5 | I7: 60.98 | J7: 0.365 | K7: 29.8 | L7: No
A8: TXN-101806 | B8: 15-03-2025 | C8: NORTH | D8: N-008 | E8: Home Goods | F8: Storage Bin | G8: Member | H8: 4 | I8: 25.7 | J8: 0.142 | K8: 9.84 | L8: No
A9: TXN-101433 | B9: 11/12/2025 | C9: East | D9: E-014 | E9: Apparel | F9: Men's T-Shirt | G9: Member | H9: 1 | I9: 60.08 | J9: 0.058 | L9: N
A10: TXN-102387 | B10: 2024-12-05 | C10: South | D10: S-010 | E10: Electronics | F10: Bluetooth Speaker | G10: Non-Member | H10: 7 | I10: 196.62 | J10: 0.22 | K10: 129.54 | L10: No
A11: TXN-106221 | B11: 06/06/2025 | C11: East | D11: E-004 | E11: Grocery | F11: Granola Pack | G11: Member | H11: 1 | I11: 5.96 | J11: 0.171 | K11: 3.38 | L11: No
A12: TXN-102190 | B12: 10/23/2025 | C12: East | D12: E-006 | E12: Electronics | F12: Power Bank | G12: Member | H12: 1 | I12: 138.17 | J12: 0.035 | K12: 101.8 | L12: N
A13: TXN-102531 | B13: 2025-03-20 | C13: North | D13: N-014 | E13: Apparel | F13: Women's Jeans | G13: Non-Member | H13: 1 | I13: 44.28 | J13: 0.083 | K13: 19.4 | L13: No
A14: TXN-103154 | B14: 2024-06-11 | C14: West | D14: W-014 | E14: Grocery | F14: Olive Oil 500ml | G14: Member | H14: 5 | I14: 22.33 | J14: 0.077 | K14: 13.14 | L14: No
A15: TXN-100097 | B15: 2024-07-21 | C15: East | D15: E-002 | E15: Beauty | F15: Lipstick | G15: Member | H15: 7 | I15: 19.83 | J15: 0.116 | K15: 6.48 | L15: Yes
A16: TXN-104210 | B16: 11/16/2025 | C16: West | D16: W-010 | E16: Electronics | F16: Power Bank | G16: Member | H16: 3 | I16: 276.09 | J16: 0.181 | K16: 204.7 | L16: No
A17: TXN-104693 | B17: 2025-06-22 | C17: South | D17: S-005 | E17: Beauty | F17: Lipstick | G17: Non-Member | H17: 1 | I17: 52.9 | J17: 0.074 | K17: 21.01 | L17: No
A18: TXN-104346 | B18: 06/21/2025 | C18: South | D18: S-008 | E18: Apparel | F18: Winter Jacket | G18: Member | H18: 1 | I18: 24.76 | J18: 0.194 | K18: 13.24 | L18: No
A19: TXN-102258 | B19: 2024-04-23 | C19: South | D19: S-005 | E19: Apparel | F19: Men's T-Shirt | G19: Member | H19: 3 | I19: 85.21 | J19: 0.191 | K19: 40.09 | L19: No
A20: TXN-106478 | B20: 07/10/2025 | C20: West | D20: W-012 | E20: Home Goods | F20: Ceramic Mug Set | G20: Member | H20: 1 | I20: 64.44 | J20: 0.033 | K20: 28.09 | L20: No
A21: TXN-105924 | B21: 10/08/2025 | C21: North | D21: N-006 | E21: Apparel | F21: Running Shoes | G21: Member | H21: 3 | I21: 70.67 | J21: 0.086 | K21: 33.36 | L21: No
... A34: TXN-104758 | B34: 2025-01-05 | C34: North | D34: N-007 | E34: Apparel | F34: Women's Jeans | G34: Member | H34: 1 | I34: 110.68 | J34: 0.047 | K34: 60.64 | L34: No
A35: TXN-105711 | B35: 2024-06-27 | C35: west | D35: W-011 | E35: Electronics | F35: Smart Watch | G35: Non-Member | H35: 5 | J35: 0.15 | K35: 35.01 | L35: No
A36: TXN-101679 | B36: 2025-05-30 | C36: North | D36: N-011 | E36: Electronics | F36: Wireless Earbuds | G36: Member | H36: 2 | I36: 107.85 | J36: 0.13 | K36: 71.4 | L36: No
A37: TXN-100251 | C37: East | D37: E-014 | E37: Grocery | F37: Olive Oil 500ml | G37: Member | H37: 1 | I37: 24.46 | J37: 0.065 | K37: 13.93 | L37: No
A38: TXN-104324 | B38: 13-10-2024 | C38: East | D38: E-001 | E38: Home Goods | F38: Storage Bin | G38: Member | H38: 2 | I38: 31.81 | J38: 0.057 | K38: 12.65 | L38: No
A39: TXN-101647 | B39: 2024-11-09 | C39: North | D39: N-009 | E39: Beauty | F39: Lipstick | G39: Non-Member | H39: 1 | I39: 53.04 | J39: 0.051 | K39: 22.72 | L39: N
A40: TXN-100095 | B40: 03/24/2025 | C40: EAST | D40: E-006 | E40: Grocery | F40: Olive Oil 500ml | G40: Non-Member | H40: 2 | I40: 9.75 | J40: 0.067 | K40: 5.7 | L40: No
A41: TXN-103312 | B41: 2025-02-18 | C41: East | D41: E-014 | E41: Beauty | F41: Face Moisturizer | G41: Member | H41: 3 | I41: 21.4 | J41: 0.055 | K41: 9.35 | L41: No
A42: TXN-101976 | B42: 08/22/2024 | C42: East | D42: E-012 | E42: Electronics | F42: Bluetooth Speaker | G42: Member | H42: 5 | I42: 155.28 | J42: 0.132 | K42: 106.13 | L42: No
A43: TXN-104508 | B43: 2024-09-19 | C43: North | D43: N-008 | E43: Electronics | F43: Wireless Earbuds | G43: Member | H43: 4 | I43: 159.04 | J43: 0.203 | K43: 121.91 | L43: No
A44: TXN-101580 | B44: 2025-07-04 | C44: West | D44: W-012 | E44: Home Goods | F44: LED Desk Lamp | G44: Non-Member | H44: 7 | I44: 19.52 | J44: 0.153 | K44: 9.46 | L44: No
A45: TXN-102446 | B45: 2025-05-13 | C45: South | D45: S-010 | E45: Apparel | F45: Running Shoes | G45: Non-Member | H45: 1 | I45: 111.81 | J45: 0.328 | K45: 58.78 | L45: No
A46: TXN-101061 | B46: 2025-02-24 | C46: South | D46: S-012 | E46: Apparel | F46: Women's Jeans | G46: Non-Member | H46: 6 | I46: 108.2 | K46: 53.41 | L46: No
A47: TXN-102571 | B47: 2025-12-10 | C47: South | D47: S-003 | E47: Beauty | F47: Lipstick | G47: Non-Member | H47: 1 | I47: 8 | J47: 0.177 | K47: 3.09 | L47: No
A48: TXN-103730 | B48: 05/29/2025 | C48: North | D48: N-015 | E48: Grocery | F48: Granola Pack | G48: Non-Member | H48: 1 | I48: 14.51 | J48: 0.084 | K48: 9.56 | L48: No
A49: TXN-100768 | B49: 06-10-2025 | C49: East | D49: E-013 | E49: Electronics | F49: Smart Watch | G49: Non-Member | H49: 1 | I49: 118.87 | J49: 0.055 | K49: 90.18 | L49: No
A50: TXN-100948 | B50: 06/30/2025 | C50: East | D50: E-009 | E50: Apparel | F50: Casual Dress | G50: Member | H50: 1 | I50: 72.4 | J50: 0.081 | K50: 39.31 | L50: No
A51: TXN-104691 | B51: 2024-11-19 | C51: East | D51: E-010 | E51: Apparel | F51: Winter Jacket | H51: 5 | I51: 69.42 | J51: 0.12 | K51: 34.6 | L51: No
A52: TXN-101903 | B52: 2025-06-05 | C52: South | D52: S-008 | E52: Home Goods | F52: Throw Pillow | G52: Non-Member | H52: 1 | I52: 63.03 | J52: 0.333 | K52: 26.82 | L52: No
...
